Workbook
Name Anfangszeit: #REF!
Name Anfangszeit: #REF!
Name Intervall: #REF!
Name Intervall: #REF!

Sheet Liste
A1: Anbieter | B1: Offered by | C1: Link Lehrstuhl
A2: Prof. Dr. Ludger Linnemann | B2: Applied Economics | C2: https://www.wiwi2.tu-dortmund.de/wiwi/ae/de/lehrstuhl/
A3: Dr. Philipp Adämmer | B3: Ökonometrie und Statistik | C3: https://www.statistik.tu-dortmund.de/oekonometrie.html
A4: Prof. Dr. Andreas Groll | B4: Statistical Methods for Big Data | C4: https://www.statistik.tu-dortmund.de/bigdata.html
A5: Prof. Dr. Wolfgang Leininger | B5: VWL (Mikroökonomie) | C5: https://www.wiwi2.tu-dortmund.de/wiwi/mik/de/lehrstuhl/index.html
A6: Prof Dr. Katja Ickstadt | B6: Mathematische Statistik und biometrische Anwendungen | C6: https://www.statistik.tu-dortmund.de/biometrie.html
A7: Prof. Dr. Christine Müller | B7: Statistik mit Anwendungen im Bereich der Ingenieurwissenschaften | C7: https://www.statistik.tu-dortmund.de/ingenieurswissenschaften.html
A8: Prof. Dr. Philip Jung | B8: Makroökonomie | C8: https://www.wiwi2.tu-dortmund.de/wiwi/mak/de/lehrstuhl/index.html
A9: Prof. Dr. Carsten Jentsch | B9: Wirtschafts- und Sozialstatistik | C9: https://www.statistik.tu-dortmund.de/iwus.html
A10: Jun.-Prof. Dr. Lars Metzger | B10: Juniorprofessur Volkswirtschaftslehre 1 | C10: https://www.wiwi2.tu-dortmund.de/wiwi/of/de/einrichtung/aktuell/index.html
A11: Prof. Dr. Peter N. Posch | B11: Professur Finance | C11: https://finance.wiwi.tu-dortmund.de/
A12: Prof. Dr. Katharina Morik Prof. Dr. Erich Schubert | B12: Lehrstuhl für Künstliche Intelligenz | C12: https://www-ai.cs.tu-dortmund.de/index.html
... A34: Jun.-Prof. Dr. Daniel Kühnle | B34: Juniorprofessur für VWL, insb. Arbeitsmarkt und Gesundheit | C34: https://www.amg.wiwi.uni-due.de

Sheet Kursliste
A1: Kurs | B1: Offered by | C1: Modulname | D1: Veranstaltungstyp | E1: Anbieter | F1: ID | G1: Tag | H1: Ort | I1: Anfangszeit | J1: Endzeit | K1: zuletzt angeboten | L1: Semester | M1: Kommentar | N1: Link_aktuelle_Veranstaltungsuebersicht | O1: MHB | P1: Link Lehrstuhl | Q1: Link Modulhandbuch | R1: Sprache | S1: ECTS | T1: Section | U1: aktuell_angeboten
A2: Advanced Business Cycle Analysis | B2: =VLOOKUP($E2,Liste!$A$2:$C$34,2,FALSE) -> Applied Economics | C2: Applied Economics III | D2: Vorlesung mit integrierter Übung | E2: Prof. Dr. Ludger Linnemann | F2: ABCA | G2: MONTAG | H2: Dortmund | I2: 14:00 | J2: 18:00 | K2: SS20 | L2: SS | N2: http://www.wiwi.tu-dortmund.de/wiwi/ae/de/lehre/veranstalt/sose/abc/index.html | O2: 32 | P2: =VLOOKUP($B2,Liste!$B$2:$C$34,2,FALSE) -> https://www.wiwi2.tu-dortmund.de/wiwi/ae/de/lehrstuhl/ | Q2: https://wiwi.tu-dortmund.de/storages/wiwi/r/studiengaenge/wiwi-master/wiwi-master-2019/ma-wiwi-2019-modulhandbuch-neu.pdf#page=85 | R2: englisch | S2: 7.5 | T2: ME5 (Economics) | U2: yes
A3: Advanced Econometrics | B3: =VLOOKUP($E3,Liste!$A$2:$C$34,2,FALSE) -> Ökonometrie und Statistik | C3: Advanced Econometrics | D3: Vorlesung | E3: Dr. Philipp Adämmer | F3: AE | G3: DIENSTAG MITTWOCH | H3: Dortmund | I3: 10:00 12:00 | J3: 12:00 14:00 | K3: WS1819 | L3: WS | N3: https://www.statistik.tu-dortmund.de/advecx-17181.html | O3: 44 | P3: =VLOOKUP($B3,Liste!$B$2:$C$34,2,FALSE) -> https://www.statistik.tu-dortmund.de/oekonometrie.html | Q3: https://www.statistik.tu-dortmund.de/fileadmin/user_upload/Studium/Vorlesungsverzeichnis/WS2017_18/Kommentierte_VVZ/Wagner_Komm._Verz._WS_2017_-_Advanced_Econometrics-1.pdf | R3: deutsch/englisch | S3: 9 | T3: ME7 (Econometric Methods) | U3: no
A4: Advanced Econometrics | B4: =VLOOKUP($E4,Liste!$A$2:$C$34,2,FALSE) -> Ökonometrie und Statistik | C4: Advanced Econometrics | D4: Übung | E4: Dr. Philipp Adämmer | F4: EX-AE | G4: MITTWOCH | H4: Dortmund | I4: 14:00 | J4: 17:00 | K4: WS1819 | L4: WS | N4: https://www.statistik.tu-dortmund.de/advecx-17181.html | O4: 44 | P4: =VLOOKUP($B4,Liste!$B$2:$C$34,2,FALSE) -> https://www.statistik.tu-dortmund.de/oekonometrie.html | Q4: https://www.statistik.tu-dortmund.de/fileadmin/user_upload/Studium/Vorlesungsverzeichnis/WS2017_18/Kommentierte_VVZ/Wagner_Komm._Verz._WS_2017_-_Advanced_Econometrics-1.pdf | R4: deutsch/englisch | S4: 9 | T4: ME7 (Econometric Methods) | U4: no
A5: Advanced Forecasting in Energy Markets | B5: =VLOOKUP($E5,Liste!$A$2:$C$34,2,FALSE) -> Chair of Environmental Economics, esp. Economics of Renewable Energy | C5: Advanced Forecasting in Energy Markets | D5: Seminar | E5: Jun.-Prof. Dr. Florian Ziel | F5: AFEM | G5: DIENSTAG | H5: Essen | I5: 0.58333333 | J5: 0.66666667 | K5: SS20 | L5: SS | N5: https://www.uee.wiwi.uni-due.de/studium-lehre/sommersemester-20/12211/ | O5: 50 | P5: =VLOOKUP($B5,Liste!$B$2:$C$34,2,FALSE) -> https://www.uee.wiwi.uni-due.de | Q5: https://www.wiwi.uni-due.de/studium/informationen-zu-den-modulen/advanced-forecasting-in-energy-markets-796/ | R5: englisch | S5: 6 | T5: ME6 (Applied Econometrics) | U5: no
A6: Advanced R for Econometricians | B6: =VLOOKUP($E6,Liste!$A$2:$C$34,2,FALSE) -> Ökonometrie | C6: Advanced R for Econometricians | D6: Vorlesung mit integrierter Übung | E6: Prof. Dr. Christoph Hanck | F6: ARE | G6: MONTAG | H6: Essen | I6: 0.58333333 | J6: 0.75 | K6: WS1920 | L6: WS | N6: https://www.oek.wiwi.uni-due.de/studium-lehre/lehrveranstaltungen/wintersemester-1920/11648/ | O6: 62 | P6: =VLOOKUP($B6,Liste!$B$2:$C$34,2,FALSE) -> https://www.oek.wiwi.uni-due.de/ | Q6: https://www.wiwi.uni-due.de/studium/informationen-zu-den-modulen/advanced-r-for-econometricians-m887/ | R6: englisch | S6: 6 | T6: ME6 (Applied Econometrics) | U6: no
A7: Advanced Statistical Learning | B7: =VLOOKUP($E7,Liste!$A$2:$C$34,2,FALSE) -> Statistical Methods for Big Data | C7: Advanced Topics in Econometric Methods | D7: Vorlesung | E7: Prof. Dr. Andreas Groll | F7: ASL | G7: DIENSTAG | H7: Dortmund | I7: 0.58333333 | J7: 0.66666667 | K7: WS2021 | L7: WS | N7: https://www.lsf.tu-dortmund.de/qisserver/rds?state=verpublish&status=init&vmfile=no&publishid=225221&moduleCall=webInfo&publishConfFile=webInfo&publishSubDir=veranstaltung | O7: 44 | P7: =VLOOKUP($B7,Liste!$B$2:$C$34,2,FALSE) -> https://www.statistik.tu-dortmund.de/bigdata.html | Q7: https://www.statistik.tu-dortmund.de/fileadmin/user_upload/Studium/Studiengaenge-Infos/ModHb_MSc_DaSc_2020.pdf#page=8 | R7: englisch | S7: 9 | T7: ME7 (Econometric Methods) | U7: yes
A8: Advanced Statistical Learning | B8: =VLOOKUP($E8,Liste!$A$2:$C$34,2,FALSE) -> Statistical Methods for Big Data | C8: Advanced Topics in Econometric Methods | D8: Vorlesung | E8: Prof. Dr. Andreas Groll | F8: ASL | G8: DONNERSTAG | H8: Dortmund | I8: 0.58333333 | J8: 0.66666667 | K8: WS2021 | L8: WS | N8: https://www.lsf.tu-dortmund.de/qisserver/rds?state=verpublish&status=init&vmfile=no&publishid=225221&moduleCall=webInfo&publishConfFile=webInfo&publishSubDir=veranstaltung | O8: 44 | P8: =VLOOKUP($B8,Liste!$B$2:$C$34,2,FALSE) -> https://www.statistik.tu-dortmund.de/bigdata.html | Q8: https://www.statistik.tu-dortmund.de/fileadmin/user_upload/Studium/Studiengaenge-Infos/ModHb_MSc_DaSc_2020.pdf#page=8 | R8: englisch | S8: 9 | T8: ME7 (Econometric Methods) | U8: yes
A9: Advanced Statistical Learning | B9: =VLOOKUP($E9,Liste!$A$2:$C$34,2,FALSE) -> Statistical Methods for Big Data | C9: Advanced Topics in Econometric Methods | D9: Übung | E9: Prof. Dr. Andreas Groll | F9: ASL-EX | G9: MONTAG | H9: Dortmund | I9: 0.5 | J9: 0.58333333 | K9: WS2021 | L9: WS | N9: https://www.lsf.tu-dortmund.de/qisserver/rds?state=verpublish&status=init&vmfile=no&publishid=225216&moduleCall=webInfo&publishConfFile=webInfo&publishSubDir=veranstaltung | O9: 38 | P9: =VLOOKUP($B9,Liste!$B$2:$C$34,2,FALSE) -> https://www.statistik.tu-dortmund.de/bigdata.html | Q9: https://www.statistik.tu-dortmund.de/fileadmin/user_upload/Studium/Studiengaenge-Infos/ModHb_MSc_DaSc_2020.pdf#page=8 | R9: englisch | S9: 9 | T9: ME7 (Econometric Methods) | U9: yes
A10: Applied Macroeconometrics | B10: =VLOOKUP($E10,Liste!$A$2:$C$34,2,FALSE) -> Applied Economics | C10: Applied Economics II | D10: Vorlesung | E10: Prof. Dr. Ludger Linnemann | F10: AM | G10: DIENSTAG | H10: Dortmund | I10: 10:00 | J10: 12:00 | K10: SS20 | L10: SS | N10: http://www.wiwi.tu-dortmund.de/wiwi/ae/de/lehre/veranstalt/sose/am/index.html | O10: 38 | P10: =VLOOKUP($B10,Liste!$B$2:$C$34,2,FALSE) -> https://www.wiwi2.tu-dortmund.de/wiwi/ae/de/lehrstuhl/ | Q10: https://wiwi.tu-dortmund.de/storages/wiwi/r/studiengaenge/wiwi-master/wiwi-master-2019/ma-wiwi-2019-modulhandbuch-neu.pdf#page=84 | R10: deutsch/englisch | S10: 7.5 | T10: ME6 (Applied Econometrics) | U10: yes
A11: Applied Macroeconometrics | B11: =VLOOKUP($E11,Liste!$A$2:$C$34,2,FALSE) -> Applied Economics | C11: Applied Economics II | D11: Übung | E11: Prof. Dr. Ludger Linnemann | F11: EX-AM | G11: DONNERSTAG | H11: Dortmund | I11: 12:00 | J11: 14:00 | K11: SS20 | L11: SS | N11: http://www.wiwi.tu-dortmund.de/wiwi/ae/de/lehre/veranstalt/sose/am/index.html | O11: 38 | P11: =VLOOKUP($B11,Liste!$B$2:$C$34,2,FALSE) -> https://www.wiwi2.tu-dortmund.de/wiwi/ae/de/lehrstuhl/ | Q11: https://wiwi.tu-dortmund.de/storages/wiwi/r/studiengaenge/wiwi-master/wiwi-master-2019/ma-wiwi-2019-modulhandbuch-neu.pdf#page=84 | R11: deutsch/englisch | S11: 7.5 | T11: ME6 (Applied Econometrics) | U11: yes
A12: Applied Monetary Economics | B12: =VLOOKUP($E12,Liste!$A$2:$C$34,2,FALSE) -> Applied Economics | C12: Applied Economics I | D12: Vorlesung mit integriertem Seminar | E12: Prof. Dr. Ludger Linnemann | F12: AME | G12: MONTAG | H12: Dortmund | I12: 12:30 | J12: 15:30 | K12: WS1920 | L12: WS | M12: Veranstaltung im WiWi-Modul "Applied Economics I" | N12: http://www.wiwi.tu-dortmund.de/wiwi/ae/de/lehre/veranstalt/ws/ame/index.html | O12: 37 | P12: =VLOOKUP($B12,Liste!$B$2:$C$34,2,FALSE) -> https://www.wiwi2.tu-dortmund.de/wiwi/ae/de/lehrstuhl/ | Q12: https://wiwi.tu-dortmund.de/storages/wiwi/r/studiengaenge/wiwi-master/wiwi-master-2019/ma-wiwi-2019-modulhandbuch-neu.pdf#page=80 | R12: deutsch/englisch | S12: 7.5 | T12: ME6 (Applied Econometrics) | U12: no
A13: Applied Time Series Analysis | B13: =VLOOKUP($E13,Liste!$A$2:$C$34,2,FALSE) -> Quantitative Analyse (Statistik/Ökonometrie) | C13: Applied Time Series Analysis | D13: Vorlesung | E13: Prof. Dr. Vasyl Golosnoy | F13: ATSA | G13: DIENSTAG | H13: Bochum | I13: 10:00 | J13: 12:00 | K13: SS20 | L13: SS | M13: Abweichend in SS17: Di 14:00 Uhr - 16:00 Uhr | N13: https://vvz.ruhr-uni-bochum.de/campus/all/event.asp?objgguid=NEW&from=&gguid=0x89F4F6E2E83C4A169B410FD74E53ED35&mode=&tguid=0x9A7B3E5DBFE949E6A3541F86071B243D&lang=de | O13: 22 | P13: =VLOOKUP($B13,Liste!$B$2:$C$34,2,FALSE) -> https://www.wiwi.ruhr-uni-bochum.de/statoek/index.html.de | Q13: https://www.wiwi.ruhr-uni-bochum.de/mam/content/dekanat/master_mhb_12.11.2020.pdf#page=434 | R13: englisch | S13: 10 | T13: ME6 (Applied Econometrics) | U13: yes
A14: Applied Time Series Analysis | B14: =VLOOKUP($E14,Liste!$A$2:$C$34,2,FALSE) -> Quantitative Analyse (Statistik/Ökonometrie) | C14: Applied Time Series Analysis | D14: Übung | E14: Prof. Dr. Vasyl Golosnoy | F14: EX-ATSA | G14: DIENSTAG | H14: Bochum | I14: 8:00 | J14: 10:00 | K14: SS20 | L14: SS | N14: https://vvz.ruhr-uni-bochum.de/campus/all/event.asp?objgguid=NEW&from=vvz&gguid=0x27E01A3F3A3B4854A2C15ADAB54934B0&mode=own&tguid=0x9A7B3E5DBFE949E6A3541F86071B243D&lang=de | O14: 22 | P14: =VLOOKUP($B14,Liste!$B$2:$C$34,2,FALSE) -> https://www.wiwi.ruhr-uni-bochum.de/statoek/index.html.de | Q14: https://www.wiwi.ruhr-uni-bochum.de/mam/content/dekanat/master_mhb_12.11.2020.pdf#page=434 | R14: englisch | S14: 10 | T14: ME6 (Applied Econometrics) | U14: yes
A15: Auctions: Theory, Applications and Experiments | B15: =VLOOKUP($E15,Liste!$A$2:$C$34,2,FALSE) -> VWL (Mikroökonomie) | C15: Mikroökonomie II | D15: Vorlesung | E15: Prof. Dr. Wolfgang Leininger | F15: ATAE | G15: MONTAG | H15: Dortmund | I15: 12:00 | J15: 14:00 | K15: SS19 | L15: SS | M15: Verantaltung im WiWi-Modul "Mikroökonomie II" | N15: https://bscw.uaruhr.de/pub/bscw.cgi/262215/teaching.html | O15: 34 | P15: =VLOOKUP($B15,Liste!$B$2:$C$34,2,FALSE) -> https://www.wiwi2.tu-dortmund.de/wiwi/mik/de/lehrstuhl/index.html | R15: englisch | S15: 4 | T15: ME5 (Economics) | U15: no
A16: Bayes-Statistik | B16: =VLOOKUP($E16,Liste!$A$2:$C$34,2,FALSE) -> Mathematische Statistik und biometrische Anwendungen | C16: Bayes-Statistik | D16: Vorlesung | E16: Prof Dr. Katja Ickstadt | F16: BS | G16: MONTAG | H16: Dortmund | I16: 10:00 | J16: 12:00 | K16: SS18 | L16: SS | N16: https://www.statistik.tu-dortmund.de/biometrie-lehre.html | O16: 44 | P16: =VLOOKUP($B16,Liste!$B$2:$C$34,2,FALSE) -> https://www.statistik.tu-dortmund.de/biometrie.html | Q16: https://www.statistik.tu-dortmund.de/fileadmin/user_upload/Studium/Vorlesungsverzeichnis/SS2017/Kommentierte_VVZ/KommentiertesVVZ__Blockkurs_Fermin.pdf | R16: deutsch | S16: 9 | T16: ME7 (Econometric Methods) | U16: no
A17: Bayes-Statistik | B17: =VLOOKUP($E17,Liste!$A$2:$C$34,2,FALSE) -> Mathematische Statistik und biometrische Anwendungen | C17: Bayes-Statistik | D17: Vorlesung | E17: Prof Dr. Katja Ickstadt | F17: BS | G17: FREITAG | H17: Dortmund | I17: 10:00 | J17: 12:00 | K17: SS18 | L17: SS | N17: https://www.statistik.tu-dortmund.de/biometrie-lehre.html | O17: 44 | P17: =VLOOKUP($B17,Liste!$B$2:$C$34,2,FALSE) -> https://www.statistik.tu-dortmund.de/biometrie.html | Q17: https://www.statistik.tu-dortmund.de/fileadmin/user_upload/Studium/Vorlesungsverzeichnis/SS2017/Kommentierte_VVZ/KommentiertesVVZ__Blockkurs_Fermin.pdf | R17: deutsch | S17: 9 | T17: ME7 (Econometric Methods) | U17: no
A18: Bayes-Statistik | B18: =VLOOKUP($E18,Liste!$A$2:$C$34,2,FALSE) -> Mathematische Statistik und biometrische Anwendungen | C18: Bayes-Statistik | D18: Übung | E18: Prof Dr. Katja Ickstadt | F18: EX-BS | G18: MONTAG | H18: Dortmund | I18: 8:00 | J18: 10:00 | K18: SS18 | L18: SS | M18: jweiels alternative Termine | N18: https://www.statistik.tu-dortmund.de/biometrie-lehre.html | O18: 44 | P18: =VLOOKUP($B18,Liste!$B$2:$C$34,2,FALSE) -> https://www.statistik.tu-dortmund.de/biometrie.html | Q18: https://www.statistik.tu-dortmund.de/fileadmin/user_upload/Studium/Vorlesungsverzeichnis/SS2017/Kommentierte_VVZ/KommentiertesVVZ__Blockkurs_Fermin.pdf | R18: deutsch | S18: 9 | T18: ME7 (Econometric Methods) | U18: no
A19: Bayes-Statistik | B19: =VLOOKUP($E19,Liste!$A$2:$C$34,2,FALSE) -> Mathematische Statistik und biometrische Anwendungen | C19: Bayes-Statistik | D19: Übung | E19: Prof Dr. Katja Ickstadt | F19: EX-BS | G19: DONNERSTAG | H19: Dortmund | I19: 10:00 | J19: 12:00 | K19: SS18 | L19: SS | M19: jweiels alternative Termine | N19: https://www.statistik.tu-dortmund.de/biometrie-lehre.html | O19: 44 | P19: =VLOOKUP($B19,Liste!$B$2:$C$34,2,FALSE) -> https://www.statistik.tu-dortmund.de/biometrie.html | Q19: https://www.statistik.tu-dortmund.de/fileadmin/user_upload/Studium/Vorlesungsverzeichnis/SS2017/Kommentierte_VVZ/KommentiertesVVZ__Blockkurs_Fermin.pdf | R19: deutsch | S19: 9 | T19: ME7 (Econometric Methods) | U19: no
A20: Bayesian Econometrics | B20: =VLOOKUP($E20,Liste!$A$2:$C$34,2,FALSE) -> Ökonometrie | C20: Fortgeschrittene Ökonometrie | D20: Vorlesung | E20: Prof. Dr. Christoph Hanck | F20: BECMX | G20: WECHSELND | H20: Essen | K20: WS1920 | L20: SS/WS | M20: Block in WS18 | N20: https://www.oek.wiwi.uni-due.de/studium-lehre/lehrveranstaltungen/wintersemester-1920/11312/ | O20: 77 | P20: =VLOOKUP($B20,Liste!$B$2:$C$34,2,FALSE) -> https://www.oek.wiwi.uni-due.de/ | Q20: https://www.wiwi.uni-due.de/studium/informationen-zu-den-modulen/fortgeschrittene-oekonometrie-75/ | R20: deutsch/englisch | S20: 3 | T20: ME7 (Econometric Methods) | U20: no
A21: Bayesian Econometrics | B21: =VLOOKUP($E21,Liste!$A$2:$C$34,2,FALSE) -> Ökonometrie | C21: Fortgeschrittene Ökonometrie | D21: Übung | E21: Prof. Dr. Christoph Hanck | F21: EX-BECMX | G21: SAMSTAG | H21: Essen | K21: WS1920 | L21: SS/WS | M21: Block in WS18 | N21: https://www.oek.wiwi.uni-due.de/studium-lehre/lehrveranstaltungen/wintersemester-1920/11311/ | O21: 77 | P21: =VLOOKUP($B21,Liste!$B$2:$C$34,2,FALSE) -> https://www.oek.wiwi.uni-due.de/ | Q21: https://www.wiwi.uni-due.de/studium/informationen-zu-den-modulen/fortgeschrittene-oekonometrie-75/ | R21: deutsch/englisch | S21: 3 | T21: ME7 (Econometric Methods) | U21: no
A22: Case Studies | B22: =VLOOKUP($E22,Liste!$A$2:$C$34,2,FALSE) -> Faculty of Statistics | C22: Case Studies | D22: Seminar | E22: Lecturers from Faculty of Statistics | F22: FSII | G22: MITTWOCH | H22: Dortmund | I22: 10:00 | J22: 14:00 | K22: WS1920 | L22: SS/WS | N22: https://www.lsf.tu-dortmund.de/qisserver/rds?state=verpublish&status=init&vmfile=no&publishid=225159&moduleCall=webInfo&publishConfFile=webInfo&publishSubDir=veranstaltung | O22: 5 | P22: =VLOOKUP($B22,Liste!$B$2:$C$34,2,FALSE) -> https://www-ai.cs.tu-dortmund.de/index.html | Q22: https://www.statistik.tu-dortmund.de/fileadmin/user_upload/Studium/Studiengaenge-Infos/ModHb_MSc_DaSc_2020.pdf#page=11 | R22: deutsch | S22: 8 | T22: ME3 | U22: yes
A23: Causality and Programme Evaluation | B23: =VLOOKUP($E23,Liste!$A$2:$C$34,2,FALSE) -> Lehrstuhl für VWL, insb. Gesundheitsökonomik | C23: Causality and Programme Evaluation | D23: Vorlesung | E23: Prof. Dr. Martin Karlsson | F23: CAPE | G23: MONTAG | H23: Essen | I23: 0.41666667 | J23: 0.5 | K23: SS18 | L23: SS | N23: https://www.goek.wiwi.uni-due.de/studium-lehre/lehrveranstaltungen/sommersemester-19/10840/ | O23: 79 | P23: =VLOOKUP($B23,Liste!$B$2:$C$34,2,FALSE) -> https://www.goek.wiwi.uni-due.de/startseite/ | Q23: https://www.wiwi.uni-due.de/studium/informationen-zu-den-modulen/causality-and-programme-evaluation-473/ | R23: englisch | S23: 3 | T23: ME7 (Econometric Methods) | U23: no
A24: Causality and Programme Evaluation | B24: =VLOOKUP($E24,Liste!$A$2:$C$34,2,FALSE) -> Lehrstuhl für VWL, insb. Gesundheitsökonomik | C24: Causality and Programme Evaluation | D24: Übung | E24: Prof. Dr. Martin Karlsson | F24: EX-CAPE | G24: MiTTWOCH | H24: Essen | I24: 0.58333333 | J24: 0.66666667 | K24: SS18 | L24: SS | N24: https://www.goek.wiwi.uni-due.de/studium-lehre/lehrveranstaltungen/sommersemester-19/10839/ | O24: 79 | P24: =VLOOKUP($B24,Liste!$B$2:$C$34,2,FALSE) -> https://www.goek.wiwi.uni-due.de/startseite/ | Q24: https://www.wiwi.uni-due.de/studium/informationen-zu-den-modulen/causality-and-programme-evaluation-473/ | R24: englisch | S24: 3 | T24: ME7 (Econometric Methods) | U24: no
A25: Current Topics in Health Economics | B25: =VLOOKUP($E25,Liste!$A$2:$C$34,2,FALSE) -> Apl.-Professur für Health Economics | C25: Current Topics in Health Economics | D25: Seminar | E25: Prof Dr. Ansgar Wübker | F25: CTHE | H25: Bochum/RGS | K25: SS20 | L25: SS | M25: In SS19: Kick-Off Meeting: 18.04.2019; Seminar: 27.06. - 28.06.2018; 9 am - 5 pm RWI Essen | N25: https://vvz.ruhr-uni-bochum.de/campus/all/event.asp?objgguid=NEW&from=vvz&gguid=0xCC7BE32B58EA4AB5BD3AECB361F94DDB&mode=own&tguid=0x9A7B3E5DBFE949E6A3541F86071B243D&lang=de | O25: 15 | P25: =VLOOKUP($B25,Liste!$B$2:$C$34,2,FALSE) -> https://www.wiwi.ruhr-uni-bochum.de/health/index.html.de | Q25: https://www.wiwi.ruhr-uni-bochum.de/mam/content/dekanat/master_mhb_12.11.2020.pdf#page=141 | R25: englisch | S25: 5 | T25: ME5 (Economics) | U25: yes
A26: Data Analysis Using Stata | B26: =VLOOKUP($E26,Liste!$A$2:$C$34,2,FALSE) -> Empirical Economics | C26: Data Analysis Using Stata | D26: Seminar | E26: Prof. Dr. Thomas K. Bauer | F26: DAUS | G26: DIENSTAG | H26: Bochum | I26: 0.58333333 | J26: 0.66666667 | K26: WS1920 | L26: WS | M26: Neue Veranstaltung | N26: https://vvz.ruhr-uni-bochum.de/campus/all/event.asp?gguid=0x2133DD1B5E6F404198A0D2B9CF0576CB&from=vvz&mode=own&tabID=1&tguid=0xF13C2A4A39064F2295BE2AE837945F8E&objgguid=NEW&lang=de | O26: 23 | P26: =VLOOKUP($B26,Liste!$B$2:$C$34,2,FALSE) -> https://www.wiwi.ruhr-uni-bochum.de/empwifo/index.html.en | Q26: http://www.wiwi.ruhr-uni-bochum.de/mam/content/dekanat/modulhandbuch__master_-wise_2018_19_21.08.2018.pdf#page=77 | R26: englisch | S26: 5 | T26: ME6 (Applied Econometrics) | U26: no
A27: Dynamic Macroeconomics | B27: =VLOOKUP($E27,Liste!$A$2:$C$34,2,FALSE) -> Makroökonomie | C27: Makroökonomie IV | D27: Vorlesung mit integrierter Übung | E27: Prof. Dr. Philip Jung | F27: DM | G27: DIENSTAG | H27: Dortmund | I27: 10:00 | J27: 14:00 | K27: WS1920 | L27: WS | M27: Veranstaltung im Modul "Makroökonomie IV" | N27: https://www.lsf.tu-dortmund.de/qisserver/rds?state=verpublish&status=init&vmfile=no&publishid=224693&moduleCall=webInfo&publishConfFile=webInfo&publishSubDir=veranstaltung | O27: 33 | P27: =VLOOKUP($B27,Liste!$B$2:$C$34,2,FALSE) -> https://www.wiwi2.tu-dortmund.de/wiwi/mak/de/lehrstuhl/index.html | Q27: https://wiwi.tu-dortmund.de/storages/wiwi/r/studiengaenge/wiwi-master/wiwi-master-2019/ma-wiwi-2019-modulhandbuch-neu.pdf#page=86 | R27: englisch | S27: 7.5 | T27: ME5 (Economics) | U27: no
A28: Dynamic Macroeconomics | B28: =VLOOKUP($E28,Liste!$A$2:$C$34,2,FALSE) -> Makroökonomie | C28: Makroökonomie IV | D28: Übung | E28: Prof. Dr. Philip Jung | F28: EX-DM | G28: DIENSTAG | H28: Dortmund | I28: 08:30:00 | J28: 10:00 | K28: WS1920 | L28: WS | M28: Veranstaltung im Modul "Makroökonomie IV" | N28: https://www.lsf.tu-dortmund.de/qisserver/rds?state=verpublish&status=init&vmfile=no&publishid=224694&moduleCall=webInfo&publishConfFile=webInfo&publishSubDir=veranstaltung | O28: 33 | P28: =VLOOKUP($B28,Liste!$B$2:$C$34,2,FALSE) -> https://www.wiwi2.tu-dortmund.de/wiwi/mak/de/lehrstuhl/index.html | Q28: https://wiwi.tu-dortmund.de/storages/wiwi/r/studiengaenge/wiwi-master/wiwi-master-2019/ma-wiwi-2019-modulhandbuch-neu.pdf#page=86 | R28: englisch | S28: 7.5 | T28: ME5 (Economics) | U28: no
A29: Econometric Evaluation of Economic Policies | B29: =VLOOKUP($E29,Liste!$A$2:$C$34,2,FALSE) -> Empirical Economics | C29: Econometric Evaluation of Economic Policies | D29: Vorlesung | E29: Prof. Dr. Thomas K. Bauer | F29: EEEP | G29: FREITAG | H29: Bochum/RGS | I29: 14:00 | J29: 16:00 | K29: SS20 | L29: SS | M29: Auch in WS1718: Fr 14:00 Uhr - 16:00 Uhr | N29: https://vvz.ruhr-uni-bochum.de/campus/all/event.asp?objgguid=NEW&from=&gguid=0x6B6CCD3F81FE49E3BCFE7A396FB4F7CC&mode=&tguid=0x9A7B3E5DBFE949E6A3541F86071B243D&lang=de | O29: 25 | P29: =VLOOKUP($B29,Liste!$B$2:$C$34,2,FALSE) -> https://www.wiwi.ruhr-uni-bochum.de/empwifo/index.html.en | Q29: https://www.wiwi.ruhr-uni-bochum.de/mam/content/dekanat/master_mhb_12.11.2020.pdf#page=112 | R29: englisch | S29: 5 | T29: ME6 (Applied Econometrics) | U29: yes
A30: Econometrics | B30: =VLOOKUP($E30,Liste!$A$2:$C$34,2,FALSE) -> Wirtschafts- und Sozialstatistik | C30: Econometrics | D30: Vorlesung mit integrierter Übung | E30: Prof. Dr. Carsten Jentsch | F30: ECMX | H30: Dortmund | K30: SS20 | L30: SS | M30: Neue Veranstaltung | N30: https://www.lsf.tu-dortmund.de/qisserver/rds?state=verpublish&status=init&vmfile=no&publishid=236695&moduleCall=webInfo&publishConfFile=webInfo&publishSubDir=veranstaltung | O30: 4 | P30: =VLOOKUP($B30,Liste!$B$2:$C$34,2,FALSE) -> https://www.statistik.tu-dortmund.de/iwus.html | R30: englisch | S30: 9 | T30: ME2 | U30: yes
A31: Econometrics II | B31: =VLOOKUP($E31,Liste!$A$2:$C$34,2,FALSE) -> Lehrstuhl für Quantitative Methoden in den Wirtschaftswissenschaften | C31: Econometrics II | D31: Vorlesung | E31: Prof. Dr. Marie Paul | F31: ECMXII | H31: MSM/RGS | K31: SS19 | L31: SS | N31: https://www.qmw.msm.uni-due.de/lehre/lehrveranstaltungen/sommersemester-21/4551/ | O31: 10 | P31: =VLOOKUP($B31,Liste!$B$2:$C$34,2,FALSE) -> https://www.qmw.msm.uni-due.de/startseite/ | Q31: http://rgs-econ.org/courses/current/ | R31: englisch | S31: 3 | T31: ME6 (Applied Econometrics) | U31: yes
A32: Econometrics II | B32: =VLOOKUP($E32,Liste!$A$2:$C$34,2,FALSE) -> Lehrstuhl für Quantitative Methoden in den Wirtschaftswissenschaften | C32: Econometrics II | D32: Übung | E32: Prof. Dr. Marie Paul | F32: EX-ECMXII | H32: MSM/RGS | K32: SS19 | L32: SS | N32: https://www.qmw.msm.uni-due.de/lehre/lehrveranstaltungen/sommersemester-21/4552/ | O32: 10 | P32: =VLOOKUP($B32,Liste!$B$2:$C$34,2,FALSE) -> https://www.qmw.msm.uni-due.de/startseite/ | Q32: http://rgs-econ.org/courses/current/ | R32: englisch | S32: 3 | T32: ME6 (Applied Econometrics) | U32: yes
A33: Econometrics of Electricity Markets | B33: =VLOOKUP($E33,Liste!$A$2:$C$34,2,FALSE) -> Chair of Environmental Economics, esp. Economics of Renewable Energy | C33: Econometrics of Electricity Markets | D33: Vorlesung | E33: Jun.-Prof. Dr. Florian Ziel | F33: ECMXEM | G33: MONTAG | H33: Essen | I33: 0.41666667 | J33: 0.5 | K33: WS1920 | L33: SS | N33: https://www.uee.wiwi.uni-due.de/studium-lehre/sommersemester-21/13269/ | O33: 64 | P33: =VLOOKUP($B33,Liste!$B$2:$C$34,2,FALSE) -> https://www.uee.wiwi.uni-due.de | Q33: https://www.wiwi.uni-due.de/studium/informationen-zu-den-modulen/econometrics-of-electricity-markets-788/ | R33: englisch | S33: 6 | T33: ME6 (Applied Econometrics) | U33: yes
A34: Econometrics of Electricity Markets | B34: =VLOOKUP($E34,Liste!$A$2:$C$34,2,FALSE) -> Chair of Environmental Economics, esp. Economics of Renewable Energy | C34: Econometrics of Electricity Markets | D34: Übung | E34: Jun.-Prof. Dr. Florian Ziel | F34: ECMXEM | G34: DIENSTAG | H34: Essen | I34: 0.33333333 | J34: 0.41666667 | K34: WS1929 | L34: SS | N34: https://www.uee.wiwi.uni-due.de/studium-lehre/sommersemester-21/13271/ | O34: 64 | P34: =VLOOKUP($B34,Liste!$B$2:$C$34,2,FALSE) -> https://www.uee.wiwi.uni-due.de | Q34: https://www.wiwi.uni-due.de/studium/informationen-zu-den-modulen/econometrics-of-electricity-markets-788/ | R34: englisch | S34: 6 | T34: ME6 (Applied Econometrics) | U34: yes
A35: Econometrics of Electricity Markets | B35: =VLOOKUP($E35,Liste!$A$2:$C$34,2,FALSE) -> Chair of Environmental Economics, esp. Economics of Renewable Energy | C35: Econometrics of Electricity Markets | D35: Übung | E35: Jun.-Prof. Dr. Florian Ziel | F35: ECMXEM | G35: DIENSTAG | H35: Essen | I35: 0.33333333 | J35: 0.41666667 | K35: WS1929 | L35: SS | N35: https://www.uee.wiwi.uni-due.de/studium-lehre/sommersemester-21/13270/ | O35: 64 | P35: =VLOOKUP($B35,Liste!$B$2:$C$34,2,FALSE) -> https://www.uee.wiwi.uni-due.de | Q35: https://www.wiwi.uni-due.de/studium/informationen-zu-den-modulen/econometrics-of-electricity-markets-788/ | R35: englisch | S35: 6 | T35: ME6 (Applied Econometrics) | U35: yes
A36: Economics of Information | B36: =VLOOKUP($E36,Liste!$A$2:$C$34,2,FALSE) -> Juniorprofessur Volkswirtschaftslehre 1 | C36: Mikroökonomie II | D36: Vorlesung | E36: Jun.-Prof. Dr. Lars Metzger | F36: EI | G36: DIENSTAG | H36: Dortmund | I36: 10:00 | J36: 12:00 | K36: WS1920 | L36: WS | M36: Vorlesung im WiWi-Modul "Mikroökonomie II" | N36: https://www.lsf.tu-dortmund.de/qisserver/rds?state=verpublish&status=init&vmfile=no&publishid=214260&moduleCall=webInfo&publishConfFile=webInfo&publishSubDir=veranstaltung#basicdata | O36: 34 | P36: =VLOOKUP($B36,Liste!$B$2:$C$34,2,FALSE) -> https://www.wiwi2.tu-dortmund.de/wiwi/of/de/einrichtung/aktuell/index.html | Q36: http://www.wiwi.tu-dortmund.de/wiwi/de/studium/studiengaenge/wiwi-master-2015/ma-wiwi-2015-modulhandbuch-neu.pdf#page=82 | R36: englisch | S36: 3.5 | T36: ME5 (Economics) | U36: no
A37: Empirische Bilanzanalyse | B37: =VLOOKUP($E37,Liste!$A$2:$C$34,2,FALSE) -> Statistik | C37: Empirische Bilanzanalyse | D37: Vorlesung | E37: Prof. Dr. Andreas Behr | F37: EBSA | G37: MONTAG | H37: Essen | I37: 0.66666667 | J37: 0.75 | K37: SS20 | L37: SS | M37: SS17 abweichend: Fr 14:00 Uhr - 18:00 Uhr | N37: https://www.stat.wiwi.uni-due.de/studium-lehre/lehrveranstaltungen/sommersemester-21/12414/ | O37: 65 | P37: =VLOOKUP($B37,Liste!$B$2:$C$34,2,FALSE) -> https://www.stat.wiwi.uni-due.de/ | Q37: https://www.wiwi.uni-due.de/studium/informationen-zu-den-modulen/empirische-bilanzanalyse-785/ | R37: deutsch | S37: 3 | T37: ME6 (Applied Econometrics) | U37: yes
A38: Empirische Bilanzanalyse | B38: =VLOOKUP($E38,Liste!$A$2:$C$34,2,FALSE) -> Statistik | C38: Empirische Bilanzanalyse | D38: Übung | E38: Prof. Dr. Andreas Behr | F38: EX-EBSA | G38: MITTWOCH | H38: Essen | I38: 0.33333333 | J38: 0.41666667 | K38: SS20 | L38: SS | M38: SS17 abweichend: Fr 12:00 Uhr - 14:00 Uhr | N38: https://www.stat.wiwi.uni-due.de/studium-lehre/lehrveranstaltungen/sommersemester-21/12414/ | O38: 65 | P38: =VLOOKUP($B38,Liste!$B$2:$C$34,2,FALSE) -> https://www.stat.wiwi.uni-due.de/ | Q38: https://www.wiwi.uni-due.de/studium/informationen-zu-den-modulen/empirische-bilanzanalyse-785/ | R38: deutsch | S38: 3 | T38: ME6 (Applied Econometrics) | U38: yes
A39: Empirische Methoden | B39: =VLOOKUP($E39,Liste!$A$2:$C$34,2,FALSE) -> Statistik | C39: Empirische Methoden | D39: Vorlesung | E39: Prof. Dr. Andreas Behr | F39: EM | G39: FREITAG | H39: Essen | I39: 0.5 | J39: 0.58333333 | K39: WS1920 | L39: WS | N39: https://www.stat.wiwi.uni-due.de/studium-lehre/lehrveranstaltungen/wintersemester-20-21/12404/ | O39: 66 | P39: =VLOOKUP($B39,Liste!$B$2:$C$34,2,FALSE) -> https://www.stat.wiwi.uni-due.de/ | Q39: https://www.wiwi.uni-due.de/studium/informationen-zu-den-modulen/empirische-methoden-508/ | R39: deutsch | S39: 3 | T39: ME6 (Applied Econometrics) | U39: no
A40: Empirische Methoden | B40: =VLOOKUP($E40,Liste!$A$2:$C$34,2,FALSE) -> Statistik | C40: Empirische Methoden | D40: Übung | E40: Prof. Dr. Andreas Behr | F40: EX-EM | G40: FREITAG | H40: Essen | I40: 0.58333333 | J40: 0.66666667 | K40: WS1920 | L40: WS | N40: https://www.stat.wiwi.uni-due.de/studium-lehre/lehrveranstaltungen/wintersemester-20-21/12404/ | O40: 66 | P40: =VLOOKUP($B40,Liste!$B$2:$C$34,2,FALSE) -> https://www.stat.wiwi.uni-due.de/ | Q40: https://www.wiwi.uni-due.de/studium/informationen-zu-den-modulen/empirische-methoden-508/ | R40: deutsch | S40: 3 | T40: ME6 (Applied Econometrics) | U40: no
...

Sheet Übersicht Winter 19
A2: course | B2: module | C2: language | D2: ECTS | E2: section | F2: offered in winter 19
A3: Advanced Business Cycle Analysis | B3: Applied Economics III | C3: englisch | D3: 7.5 | E3: ME5 (Economics) | F3: no
A4: Advanced Econometrics | B4: Advanced Econometrics | C4: deutsch/englisch | D4: 9 | E4: ME7 (Econometric Methods) | F4: no
A5: Advanced Forecasting in Energy Markets | B5: Advanced Forecasting in Energy Markets | C5: englisch | D5: 6 | E5: ME6 (Applied Econometrics) | F5: no
A6: Advanced R for Econometricians | B6: Advanced R for Econometricians | C6: englisch | D6: 6 | E6: ME6 (Applied Econometrics) | F6: yes
A7: Advanced Statistical Learning | B7: Advanced Topics in Econometric Methods | C7: englisch | D7: 9 | E7: ME7 (Econometric Methods) | F7: yes
A8: Applied Macroeconometrics | B8: Applied Economics II | C8: deutsch/englisch | D8: 7.5 | E8: ME6 (Applied Econometrics) | F8: no
A9: Applied Monetary Economics | B9: Applied Economics I | C9: deutsch/englisch | D9: 3.5 | E9: ME5 (Economics) | F9: yes
A10: Applied Time Series Analysis | B10: Applied Time Series Analysis | C10: englisch | D10: 10 | E10: ME6 (Applied Econometrics) | F10: no
A11: Auctions: Theory, Applications and Experiments | B11: Mikroökonomie II | C11: englisch | D11: 4 | E11: ME5 (Economics) | F11: no
A12: Bayes-Statistik | B12: Bayes-Statistik | C12: deutsch | D12: 9 | E12: ME7 (Econometric Methods) | F12: no
A13: Bayesian Econometrics | B13: Fortgeschrittene Ökonometrie | C13: englisch | D13: 6 | E13: ME7 (Econometric Methods) | F13: yes
A14: Case Studies | B14: Case Studies | C14: deutsch | D14: 8 | E14: ME3 | F14: yes
... A36: International Capital Movements | B36: International Capital Movements | C36: englisch | D36: 6 | E36: ME5 (Economics) | F36: no
A37: Maschinelles Lernen | B37: Maschinelles Lernen | C37: deutsch | E37: ME6 (Applied Econometrics) | F37: yes
A38: Microeconometrics | B38: Microeconometrics | C38: englisch | D38: 10 | E38: ME7 (Econometric Methods) | F38: no
A39: Microeconometrics and Empirical Applications | B39: Wirtschaftspolitik II | C39: deutsch/englisch | D39: 7.5 | E39: ME6 (Applied Econometrics) | F39: yes
A40: Mikroökonometrie / Microeconometrics | B40: Mikroökonometrie / Microeconometrics | C40: englisch | D40: 6 | E40: ME6 (Applied Econometrics) | F40: no
A41: Multivariate Statistical Methods | B41: Multivariate Statistical Methods | C41: englisch | D41: 10 | E41: ME7 (Econometric Methods) | F41: no
A42: Netzwerkanalyse | B42: Advanced Topics in Econometric Methods | C42: deutsch | D42: 9 | E42: ME7 (Econometric Methods) | F42: yes
A43: Neuere Entwicklungen der Mikroökonomik | B43: Neuere Entwicklungen der Mikroökonomik | C43: englisch | D43: 6 | E43: ME5 (Economics) | F43: yes
A44: Nonparametric Econometrics | B44: Fortgeschrittene Ökonometrie | C44: englisch | D44: 6 | E44: ME7 (Econometric Methods) | F44: no
A45: Portfolio Management | B45: Portfolio Management | C45: deutsch/englisch | D45: 6 | E45: ME6 (Applied Econometrics) | F45: no
A46: Practising Econometric Research | B46: Practising Econometric Research | C46: englisch | D46: 6 | E46: ME6 (Applied Econometrics) | F46: yes
A47: Public Economics | B47: Public Economics | C47: englisch | D47: 10 | E47: ME5 (Economics) | F47: no
A48: Quantitative Climate Finance | B48: Quantitative Climate Finance | C48: englisch | D48: 6 | E48: ME6 (Applied Econometrics) | F48: no
A49: Quantitative Finance | B49: Finance I | C49: englisch | D49: 4 | E49: ME5 (Economics) | F49: no
... A73: Wissensentdeckung in Datenbanken | B73: Wissensentdeckung in Datenbanken | C73: deutsch | D73: 8 | E73: ME6 (Applied Econometrics) | F73: no
