Workbook
Name Anfangszeit: #REF!
Name Anfangszeit: #REF!
Name Intervall: #REF!
Name Intervall: #REF!

Sheet Liste
A1: Anbieter | B1: Offered by | C1: Link Lehrstuhl
A2: Prof. Dr. Vasyl Golosnoy | B2: Chair of Statistics/Econometrics | C2: https://www.wiwi.ruhr-uni-bochum.de/statoek/index.html.en
A3: Prof Dr. Ansgar Wübker | B3: Adjunct Professorship of Health Economics | C3: https://www.wiwi.ruhr-uni-bochum.de/health/index.html.en
A4: Prof. Dr. Thomas K. Bauer | B4: Chair of Empirical Economics | C4: https://www.wiwi.ruhr-uni-bochum.de/empwifo/index.html.en
A5: Dr. Bodo Knoll | B5: Chair of Public Finance and Economic Policy | C5: https://www.wiwi.ruhr-uni-bochum.de/fiwipo/index.html.en
A6: Prof. Dr. Dr. h.c. Christoph M. Schmidt | B6: Chair of Economic Policy and Applied Econometrics | C6: https://www.wiwi.ruhr-uni-bochum.de/wipooek/index.html.en
A7: Prof. Dr. Ansgar Wübker | B7: Adjunct Professorship of Health Economics | C7: https://www.wiwi.ruhr-uni-bochum.de/health/index.html.en
A8: Apl. Prof. Dr. Manuel Frondel | B8: Chair of Energy Economics and Applied Econometrics | C8: https://www2.wiwi.rub.de/en/chairs/energy-economics-and-applied-econometrics-en/
A9: Prof. Dr. Thushyanthan Baskaran | B9: Chair for Public and Regional Economics | C9: https://www2.wiwi.rub.de/en/chairs/public-and-regional-economics/
A10: Prof. Dr. Julio R. Robledo | B10: Chair of Applied Microeconomics | C10: http://www.wiwi.ruhr-uni-bochum.de/appliedmicro/index.html.en
A11: Jun.-Prof. Dr. Sanne Kruse-Becher | B11: Chair of Macroeconomics | C11: https://www2.wiwi.rub.de/lehrstuehle/juniorprofessur-makrooekonomik/
A12: Prof. Dr. Michael Roos | B12: Chair of Macroeconomics | C12: https://www.ruhr-uni-bochum.de/mak/index.html.en
... A27: Prof. Galina Zudenkova, Ph.D. | B27: Chair of Public Economics | C27: https://of.wiwi.tu-dortmund.de/en/?tabindex=1&cHash=36002773b4bac336dae210da5a9a09fe
A28: Dr. David Rügamer
A29: Prof. Dr. Katja Ickstadt | B29: Chair of Mathematical Statistics with Applications in Biometrics | C29: https://www.statistik.tu-dortmund.de/biometrie.html
A30: Prof. Dr. Christine Müller | B30: Chair of Statistics with Applications in the Field of Engineering Sciences | C30: https://www.statistik.tu-dortmund.de/ingenieurswissenschaften.html
A31: Prof. Dr. Philip Jung | B31: Professorship Macroeconomics | C31: https://www.wiwi2.tu-dortmund.de/wiwi/mak/de/lehrstuhl/index.html
A32: Prof. Dr. Carsten Jentsch | B32: Chair of Business and Social Statistics | C32: https://www.statistik.tu-dortmund.de/iwus.html
A33: Prof. Dr. Peter N. Posch | B33: Professorship of Finance | C33: https://finance.wiwi.tu-dortmund.de/
A34: Prof. Dr. Katharina Morik | B34: Chair of Artificial Intelligence | C34: https://www-ai.cs.tu-dortmund.de/index.html
A35: Prof. Dr. Kornelius Kraft | B35: Chair of Economic Policy | C35: https://www.wiwi2.tu-dortmund.de/wiwi/wp/de/lehrstuhl/index.html
A36: Prof. Dr. Roland Fried | B36: Chair of Mathematical Statistics and Applications in Sciences | C36: https://www.statistik.tu-dortmund.de/naturwissenschaften.html
A37: Dr. Paul Wiemann | B37: Chair of Computational Statistics | C37: https://www.statistik.tu-dortmund.de/computationalstats.html
A38: Prof. Dr. Henrik Müller-Josuweit | B38: Department of Cultural Studies | C38: https://kuwi.tu-dortmund.de/studium/
A39: Dr. Matthias Westphal | B39: Department of Business and Economics | C39: https://www.tu-dortmund.de/en/university/departments/business-and-economics/
A40: Prof. Dr. Nadja Klein | B40: Chair of Uncertainty Quantification and Statistical Learning | C40: https://www.tu-dortmund.de/universitaet/neuberufene-professorinnen/prof-nadja-klein/
... A62: Prof. Dr. Yannick Hoga | B62: Lehrstuhl für Finanzmarktökonometrie | C62: https://www.oek.wiwi.uni-due.de/

Sheet Kursliste
A1: Kurs | B1: Modulname | C1: Offered by | D1: Veranstaltungstyp | E1: Anbieter | F1: Ort | G1: Semester | H1: CP | I1: Modulgruppe | J1: Link_aktuelle_Veranstaltungsuebersicht | K1: MHB | L1: Sprache | M1: aktuell_angeboten
A2: Statistical Theory | B2: Statistical Theory | C2: =VLOOKUP($E2,Liste!$A$2:$C$59,2,FALSE) -> Chair of Mathematical Statistics with Applications in Biometrics | D2: Vorlesung + Übung | E2: Prof. Dr. Katja Ickstadt | F2: Dortmund | G2: WS | H2: 10 | I2: ME1a | J2: https://www.lsf.tu-dortmund.de/qisserver/rds?state=verpublish&status=init&vmfile=no&publishid=271718&moduleCall=webInfo&publishConfFile=webInfo&publishSubDir=veranstaltung | K2: 3 | L2: englisch | M2: no | N2: x
A3: Asymptotic Theory | B3: Asymptotic Theory | C3: =VLOOKUP($E3,Liste!$A$2:$C$59,2,FALSE) -> Chair of Business and Social Statistics | D3: Vorlesung + Übung | E3: Prof. Dr. Carsten Jentsch | F3: Dortmund | G3: WS | H3: 5 | I3: ME1b | J3: https://www.lsf.tu-dortmund.de/qisserver/rds?state=verpublish&status=init&vmfile=no&publishid=271722&moduleCall=webInfo&publishConfFile=webInfo&publishSubDir=veranstaltung | K3: 4 | L3: englisch | M3: no | N3: x
A4: Econometrics | B4: Econometrics | C4: =VLOOKUP($E4,Liste!$A$2:$C$59,2,FALSE) -> Chair of Econometrics and Statistics | D4: Vorlesung + Übung | E4: Prof. Dr. Matei Demetrescu | F4: Dortmund | G4: WS/SS | H4: 9 | I4: ME2 | J4: https://www.lsf.tu-dortmund.de/qisserver/rds?state=verpublish&status=init&vmfile=no&publishid=316210&moduleCall=webInfo&publishConfFile=webInfo&publishSubDir=veranstaltung | K4: 5 | L4: englisch | M4: yes | N4: x
A5: Recent Developments in Econometrics | B5: Econometrics | C5: =VLOOKUP($E5,Liste!$A$2:$C$59,2,FALSE) -> Chair of Econometrics | D5: Vorlesung + Übung | E5: Prof. Dr. Christoph Hanck | F5: Essen | G5: WS | H5: 9 | I5: ME2 | J5: https://campus.uni-due.de/lsf/rds?state=verpublish&status=init&vmfile=no&publishid=390766&moduleCall=webInfo&publishConfFile=webInfo&publishSubDir=veranstaltung | K5: 5 | L5: englisch | M5: no | N5: x
A6: Case Studies | B6: Advanced Case Studies | C6: =VLOOKUP($E6,Liste!$A$2:$C$59,2,FALSE) -> Chair of Econometrics and Statistics | D6: Seminar | E6: Prof. Dr. Matei Demetrescu | F6: Dortmund | G6: WS/SS | H6: 8 | I6: ME3 | J6: https://www.lsf.tu-dortmund.de/qisserver/rds?state=verpublish&status=init&vmfile=no&publishid=302843&moduleCall=webInfo&publishConfFile=webInfo&publishSubDir=veranstaltung | K6: 6 | L6: englisch | M6: yes | N6: x | O6: Modul steht im Handbuch als "Advanced Case Studies" und im lsf in Dortmund als "Fallstudien 2/Case Studies"; wird lt. LSF von Prof. Dr. Christine Müller angeboten
A7: Time Series Analysis | B7: Time Series Analysis | C7: =VLOOKUP($E7,Liste!$A$2:$C$59,2,FALSE) -> Chair of Econometrics | D7: Vorlesung + Übung | E7: JProf. Dr. Antonia Arsova | F7: Dortmund | G7: SS | H7: 10 | I7: ME4 | J7: https://www.lsf.tu-dortmund.de/qisserver/rds?state=verpublish&status=init&vmfile=no&publishid=302811&moduleCall=webInfo&publishConfFile=webInfo&publishSubDir=veranstaltung | K7: 7 | L7: englisch | M7: yes | N7: x
A8: Seminar in Advanced International Trade | B8: Seminar in Adcanced International Trade | C8: =VLOOKUP($E8,Liste!$A$2:$C$59,2,FALSE) -> Chair of Macroeconomics | D8: Seminar | E8: Jun.-Prof. Dr. Sanne Kruse-Becher | F8: Bochum | G8: WS | H8: 5 | I8: ME5 | J8: https://vvz.ruhr-uni-bochum.de/campus/all/event.asp?objgguid=NEW&from=vvz&gguid=0x0048608A7AE2477B9CA6172EDCAA99E2&mode=own&tguid=0xBEC4EBD3E08E451BB6DEBD69F230152F&lang=de | K8: 18 | L8: englisch | M8: no | N8: x
A9: Current Topics in Health Economics | B9: Current Topics in Health Economics | C9: =VLOOKUP($E9,Liste!$A$2:$C$59,2,FALSE) -> Adjunct Professorship of Health Economics | D9: Seminar | E9: Prof Dr. Ansgar Wübker | F9: Bochum | G9: SS | H9: 5 | I9: ME5 | J9: https://vvz.ruhr-uni-bochum.de/campus/all/module.asp?gguid=0xFA8D9EA3133E4F6DB37192C38E8B1A44&tguid=0x32F038F554334DC3AB9024E476ECAE2E&lang=en | K9: 19 | L9: englisch | M9: yes | N9: x
A10: Economic Policy and the Media | B10: Economic Policy and the Media | C10: =VLOOKUP($E10,Liste!$A$2:$C$59,2,FALSE) -> Chair of Macroeconomics | D10: Seminar | E10: Prof. Dr. Michael Roos | F10: Bochum | G10: SS | H10: 5 | I10: ME5 | J10: https://vvz.ruhr-uni-bochum.de/campus/all/module.asp?gguid=0xFA8D9EA3133E4F6DB37192C38E8B1A44&tguid=0x32F038F554334DC3AB9024E476ECAE2E&lang=en | K10: 20 | L10: englisch | M10: yes | N10: x
A11: Economics of Innovation | B11: Economics of Innovation | C11: =VLOOKUP($E11,Liste!$A$2:$C$59,2,FALSE) -> Chair of Applied Microeconomics | D11: Vorlesung + Übung | E11: Prof. Dr. Julio R. Robledo | F11: Bochum | G11: WS | H11: 10 | I11: ME5 | J11: https://www2.wiwi.rub.de/en/chairs/applied-microeconomics/ | K11: 21 | L11: englisch | M11: no | N11: x
A12: Labor Economics | B12: Labor Economics | C12: =VLOOKUP($E12,Liste!$A$2:$C$59,2,FALSE) -> Chair of Empirical Economics | D12: Vorlesung + Übung | E12: Prof. Dr. Thomas K. Bauer | F12: Bochum | G12: SS | H12: 5 | I12: ME5 | J12: https://vvz.ruhr-uni-bochum.de/campus/all/module.asp?gguid=0xB3A61A7AF4944F6DB1D6AF88F9B7E6D0&tguid=0x32F038F554334DC3AB9024E476ECAE2E&lang=en | K12: 22 | L12: englisch | M12: yes | N12: x
A13: Macroeconomics II | B13: Macroeconomics II | C13: =VLOOKUP($E13,Liste!$A$2:$C$59,2,FALSE) -> Chair of Macroeconomics | D13: Vorlesung + Übung | E13: Prof. Dr. Michael Roos | F13: Bochum | G13: WS | H13: 5 | I13: ME5 | J13: https://vvz.ruhr-uni-bochum.de/campus/all/event.asp?objgguid=NEW&from=vvz&gguid=0x85D22DC77A4B4952A6D724E7F54D6F30&mode=own&tguid=0xBEC4EBD3E08E451BB6DEBD69F230152F&lang=de | K13: 23 | L13: englisch | M13: no | N13: x
A14: Market- and Non-Market Valuation of Environmental Goods | B14: Market- and Non-Market Valuation of Environmental Goods | C14: =VLOOKUP($E14,Liste!$A$2:$C$59,2,FALSE) -> Chair of Energy Economics and Applied Econometrics | D14: Seminar | E14: Apl. Prof. Dr. Manuel Frondel | F14: RWI, Bochum | G14: WS | H14: 5 | I14: ME5 | J14: https://vvz.ruhr-uni-bochum.de/campus/all/event.asp?objgguid=NEW&from=vvz&gguid=0xB24C649577364CBF93E96C2C8B89B66A&mode=own&tguid=0xBEC4EBD3E08E451BB6DEBD69F230152F&lang=de | K14: 24 | L14: englisch | M14: no | N14: x
A15: Microeconomics I | B15: Microeconomics I | C15: =VLOOKUP($E15,Liste!$A$2:$C$59,2,FALSE) -> Chair of Applied Microeconomics | D15: Vorlesung + Übung | E15: Prof. Dr. Julio R. Robledo | F15: Bochum | G15: WS | H15: 5 | I15: ME5 | J15: https://vvz.ruhr-uni-bochum.de/campus/all/event.asp?objgguid=NEW&from=vvz&gguid=0x012C08A055EF4D189ECD2B1C4295D8EE&mode=own&tguid=0xBEC4EBD3E08E451BB6DEBD69F230152F&lang=de | K15: 25 | L15: englisch | M15: no | N15: x
A16: Microeconomics II | B16: Macroeconomics II | C16: =VLOOKUP($E16,Liste!$A$2:$C$59,2,FALSE) -> Chair of Applied Microeconomics | D16: Vorlesung + Übung | E16: Prof. Dr. Julio R. Robledo | F16: Bochum | G16: WS | H16: 5 | I16: ME5 | J16: https://vvz.ruhr-uni-bochum.de/campus/all/event.asp?gguid=0x112BEFA687E54792A3C3AA75196B6962&from=&tabID=1&tguid=0xBEC4EBD3E08E451BB6DEBD69F230152F&objgguid=NEW&lang=de | K16: 26 | L16: englisch | M16: no | N16: x
A17: Network Economics | B17: Network Economics | C17: =VLOOKUP($E17,Liste!$A$2:$C$59,2,FALSE) -> Chair of Applied Microeconomics | D17: Vorlesung + Übung | E17: Prof. Dr. Julio R. Robledo | F17: Bochum | G17: SS | H17: 5 | I17: ME5 | J17: https://vvz.ruhr-uni-bochum.de/campus/all/module.asp?gguid=0xE0F1CDEB5C414EA8A26296016B45A91C&tguid=0x32F038F554334DC3AB9024E476ECAE2E&lang=en | K17: 27 | L17: englisch | M17: yes | N17: x
A18: Public Economics | B18: Public Economics | C18: =VLOOKUP($E18,Liste!$A$2:$C$59,2,FALSE) -> Chair for Public and Regional Economics | D18: Vorlesung + Übung | E18: Prof. Dr. Thushyanthan Baskaran | F18: Bochum | G18: SS | H18: 10 | I18: ME5 | J18: https://vvz.ruhr-uni-bochum.de/campus/all/module.asp?gguid=0x45887B9DB6A64E11AEB5704840F69E67&tguid=0x32F038F554334DC3AB9024E476ECAE2E&lang=en | K18: 28 | L18: englisch | M18: yes | N18: x
... A23: Data Analysis Using R | B23: Data Analysis Using R | C23: =VLOOKUP($E23,Liste!$A$2:$C$59,2,FALSE) -> Chair of Empirical Economics | D23: Seminar | E23: Prof. Dr. Thomas K. Bauer | F23: Bochum | G23: WS | H23: 10 | I23: ME6 | J23: https://vvz.ruhr-uni-bochum.de/campus/all/event.asp?objgguid=NEW&from=vvz&gguid=0x30DAA21C003447458FA1DC079ABB1C2D&mode=own&tguid=0x9D4A62BEDC1545CCA9363F44843B7C6F&lang=de | K23: 34 | L23: englisch | M23: no | N23: x
A24: Introduction to Empirical Macroeconomics | B24: Introduction to Empirical Macroeconomics | C24: Chair of Empirical Macroeconomics | D24: Vorlesung | E24: Apl. Prof. Dr. Torsten Schmidt | F24: Bochum | G24: WS | H24: 10 | I24: ME6 | J24: https://vvz.ruhr-uni-bochum.de/campus/all/event.asp?objgguid=NEW&from=vvz&gguid=0x72EDC5F91FED493988770FDBE6379A20&mode=own&tguid=0xBEC4EBD3E08E451BB6DEBD69F230152F&lang=de | K24: 35 | L24: englisch | M24: no | N24: x
A25: Econometric Evaluation of Economic Policies | B25: Econometric Evaluation of Economic Policies | C25: =VLOOKUP($E25,Liste!$A$2:$C$59,2,FALSE) -> Chair of Empirical Economics | D25: Vorlesung | E25: Prof. Dr. Thomas K. Bauer | F25: Bochum | G25: SS | H25: 5 | I25: ME6 | J25: https://vvz.ruhr-uni-bochum.de/campus/all/module.asp?gguid=0x7A9EEB44428D46EAA5E889EB8130AD25&tguid=0x32F038F554334DC3AB9024E476ECAE2E&lang=en | K25: 36 | L25: englisch | M25: yes | N25: x
A26: Machine Learning and Programming in Python | B26: Machine Learning and Programming in Python | C26: =VLOOKUP($E26,Liste!$A$2:$C$59,2,FALSE) -> Data Science in Economics | D26: Vorlesung | E26: Prof. Dr. Astrid Krenz | F26: Bochum | G26: WS | H26: 5 | I26: ME6 | J26: https://vvz.ruhr-uni-bochum.de/campus/all/module.asp?gguid=0xD076B65EC9214F87B4C2FCA23D8EDABB&tguid=0x32F038F554334DC3AB9024E476ECAE2E&lang=en | K26: 37 | L26: englisch | M26: yes | N26: x
A27: Seminar in Quantitative Regional Economics | B27: Quantitative Regional Economics | C27: Chair of Macroeconomics | D27: Seminar | E27: Prof. Dr. Michael Roos | F27: Bochum | G27: WS/SS | H27: 5 | I27: ME6 | J27: https://vvz.ruhr-uni-bochum.de/campus/all/module.asp?gguid=0xC3A9DE0C6AEE44A19B8F11D65C527642&tguid=0x32F038F554334DC3AB9024E476ECAE2E&lang=en | K27: 38 | L27: englisch | M27: yes | N27: x
A28: Seminar in Microeconometrics | B28: Seminar in Microeconometrics | C28: =VLOOKUP($E28,Liste!$A$2:$C$59,2,FALSE) -> Chair of Empirical Economics | D28: Seminar | E28: Prof. Dr. Thomas K. Bauer | F28: Bochum | G28: as offered | H28: 10 | I28: ME6 | J28: https://www.wiwi.ruhr-uni-bochum.de/empwifo/lehre/kurs.html.en | K28: 39 | L28: englisch | M28: no | N28: x
A29: Financial Econometrics | B29: Financial Econometrics | C29: =VLOOKUP($E29,Liste!$A$2:$C$59,2,FALSE) -> Chair of Statistics/Econometrics | D29: Vorlesung + Übung | E29: Prof. Dr. Vasyl Golosnoy | F29: Bochum | G29: WS | H29: 10 | I29: ME7 | J29: https://vvz.ruhr-uni-bochum.de/campus/all/event.asp?objgguid=NEW&from=vvz&gguid=0x45D9988EA76546E7AFDFC11D18A84D4E&mode=own&tguid=0xBEC4EBD3E08E451BB6DEBD69F230152F&lang=de | K29: 40 | L29: englisch | M29: no | N29: x
A30: Introduction to Artificial Intelligence | B30: Introduction to Artificial Intelligence | C30: =VLOOKUP($E30,Liste!$A$2:$C$59,2,FALSE) -> Faculty of Computer Science | D30: Vorlesung + Übung | E30: Lecturers from Faculty of Computer Science | F30: Bochum | G30: SS | H30: 5 | I30: ME7 | J30: https://vvz.ruhr-uni-bochum.de/campus/all/event.asp?objgguid=NEW&from=&gguid=0x750168FE52FC40F19A67859CF295CC4A&mode=&tguid=0x465D15D340584F31963F02CDAA33142A&lang=de | K30: 41 | L30: englisch | M30: no | N30: x
A31: Introduction to Microeconometrics | B31: Introduction to Microeconometrics | C31: =VLOOKUP($E31,Liste!$A$2:$C$59,2,FALSE) -> Chair of Empirical Economics | D31: Vorlesung + Übung | E31: Prof. Dr. Thomas K. Bauer | F31: Bochum | G31: SS | H31: 5 | I31: ME6 | J31: Module: Introduction to Microeconometrics | K31: 42 | L31: englisch | M31: yes | N31: x
A32: Multivariate Statistical Methods | B32: Multivariate Statistical Methods | C32: =VLOOKUP($E32,Liste!$A$2:$C$59,2,FALSE) -> Chair of Statistics/Econometrics | D32: Vorlesung + Übung | E32: Prof. Dr. Vasyl Golosnoy | F32: Bochum | G32: WS/SS | H32: 10 | I32: ME7 | J32: https://vvz.ruhr-uni-bochum.de/campus/all/event.asp?objgguid=NEW&from=&gguid=0xD39F47E023D943FD90B5A71EB54DEBA3&mode=&tguid=0x465D15D340584F31963F02CDAA33142A&lang=de | K32: 43 | L32: englisch | M32: no | N32: x | O32: Dieses Semester auf Deutsch angeboten
A33: Seminar in Econometrics | B33: Seminar in Econometrics | C33: =VLOOKUP($E33,Liste!$A$2:$C$59,2,FALSE) -> Chair of Statistics/Econometrics | D33: Seminar | E33: Prof. Dr. Vasyl Golosnoy | F33: Bochum | G33: WS/SS | H33: 10 | I33: ME7 | J33: https://vvz.ruhr-uni-bochum.de/campus/all/event.asp?objgguid=NEW&from=vvz&gguid=0x66FBD53634C446DC971FD31951253291&mode=own&tguid=0x465D15D340584F31963F02CDAA33142A&lang=de | K33: 44 | L33: englisch | M33: no | N33: x
A34: Seminar in Applied Economic Policy | B34: Seminar in Applied Economic Policy | C34: =VLOOKUP($E34,Liste!$A$2:$C$59,2,FALSE) -> Chair of Economic Policy and Applied Econometrics | D34: Seminar | E34: Prof. Dr. Dr. h.c. Christoph M. Schmidt | F34: Bochum | G34: WS/SS | H34: 5 | I34: ME5 | J34: https://vvz.ruhr-uni-bochum.de/campus/all/event.asp?objgguid=NEW&from=&gguid=0xEF7531827E52442C86AB5E151351D792&mode=&tguid=0x465D15D340584F31963F02CDAA33142A&lang=de | K34: 45 | L34: englisch | M34: no | N34: x
A35: Advances in Public Economics and Political Economy | B35: Advances in Public Economics and Political Economy | C35: =VLOOKUP($E35,Liste!$A$2:$C$59,2,FALSE) -> Chair of Public Economics | D35: Vorlesung + Übung | E35: Prof. Galina Zudenkova, Ph.D. | F35: Dortmund | G35: SS | H35: 7.5 | I35: ME5 | J35: https://www.lsf.tu-dortmund.de/qisserver/rds?state=verpublish&status=init&vmfile=no&publishid=281925&moduleCall=webInfo&publishConfFile=webInfo&publishSubDir=veranstaltung | L35: englisch | M35: no | N35: x
A36: Advanced Business Cycle Analysis | B36: Applied Economics III | C36: Professorship of Applied Economics | D36: Vorlesung + Übung | E36: Prof. Dr. Ludger Linnemann | F36: Dortmund | G36: SS | H36: 7.5 | I36: ME5 | J36: https://www.lsf.tu-dortmund.de/qisserver/rds?state=verpublish&status=init&vmfile=no&publishid=317903&moduleCall=webInfo&publishConfFile=webInfo&publishSubDir=veranstaltung | K36: 46 | L36: englisch | M36: yes | N36: x
A37: Law and Economics | B37: Law and Economics | C37: Professorship of Public Economics | D37: Vorlesung + Übung | E37: Prof. Galina Zudenkova, Ph.D. | F37: Dortmund | G37: WS | H37: 7.5 | I37: ME5 | J37: https://of.wiwi.tu-dortmund.de/en/teaching/winter-term/law-and-economics/ | L37: englisch | M37: no | N37: x
A38: Labor Economics | B38: Labor Economics | C38: Chair of Empirical Economic Research | D38: Vorlesung + Übung | E38: Prof. Dr. Michael Böhm | F38: Dortmund | G38: WS | H38: 7.5 | I38: ME5 | J38: https://www.lsf.tu-dortmund.de/qisserver/rds?state=verpublish&status=init&vmfile=no&publishid=287134&moduleCall=webInfo&publishConfFile=webInfo&publishSubDir=veranstaltung | K38: 50 | L38: englisch | M38: no | N38: x
A39: Economic growth and historical development | B39: Makroökonomie I (Economic growth and historical development) | C39: Chair of Economics 1 | D39: Vorlesung + Übung | E39: Jprof. Dr. Nina Boberg-Fazlic | F39: Dortmund | G39: WS | H39: 7.5 | I39: ME5 | J39: https://vwl1.wiwi.tu-dortmund.de/lehre/wintersemester/economic-growth/ | K39: 51 | L39: englisch | M39: no | N39: x
A40: Dynamic Macroeconomics | B40: Makroökonomie IV (Macroeconomics) | C40: =VLOOKUP($E40,Liste!$A$2:$C$59,2,FALSE) -> Professorship Macroeconomics | D40: Vorlesung + Übung | E40: Prof. Dr. Philip Jung | F40: Dortmund | G40: WS | H40: 7.5 | I40: ME5 | J40: https://makro.wiwi.tu-dortmund.de/lehre/wintersemester/dynamic-macro/ | K40: 53 | L40: englisch | M40: no | N40: x
A41: Game Theory | B41: Mikroökonomie I | D41: Vorlesung + Übung | E41: Kramm, Michael | F41: Dortmund | G41: SS | H41: 7.5 | I41: ME5 | J41: https://www.lsf.tu-dortmund.de/qisserver/rds?state=verpublish&status=init&vmfile=no&publishid=317835&moduleCall=webInfo&publishConfFile=webInfo&publishSubDir=veranstaltung | K41: 55 | L41: englisch | M41: yes | N41: x
A42: Narrative Economics and the Media | B42: Narrative Economics and the Media | C42: =VLOOKUP($E42,Liste!$A$2:$C$59,2,FALSE) -> Department of Cultural Studies | D42: Vorlesung mit integriertem Seminar | E42: Prof. Dr. Henrik Müller-Josuweit | F42: Dortmund | G42: SS | H42: 7.5 | I42: ME5 | J42: https://www.lsf.tu-dortmund.de/qisserver/rds?state=verpublish&status=init&vmfile=no&publishid=318355&moduleCall=webInfo&publishConfFile=webInfo&publishSubDir=veranstaltung | K42: 56 | L42: englisch | M42: yes | N42: x
A43: Seminar Microeconomics | B43: Seminar Microeconomics | C43: Chair of Microeconomic Theory | D43: Seminar | E43: Prof. Dr. Lukas Buchheim | F43: Dortmund | G43: WS | H43: 7.5 | I43: ME5 | J43: https://www.lsf.tu-dortmund.de/qisserver/rds?state=verpublish&status=init&vmfile=no&publishid=306006&moduleCall=webInfo&publishConfFile=webInfo&publishSubDir=veranstaltung | K43: 57 | L43: englisch | M43: no | N43: x | O43: Andere Lehrperson zugeordnet: Dr. Michael Kramm; aber findet wiedersprechend der Angabe dieses Semester statt
A44: Soziale Sicherung | B44: Soziale Sicherung | C44: Department of Business and Economics | D44: Seminar | E44: Dr. Matthias Westphal | F44: Dortmund | G44: As offered | H44: 7.5 | I44: ME5 | J44: https://vwl2.wiwi.tu-dortmund.de/lehre/sommersemester/projektseminar-soziale-sicherung/ | K44: 58 | L44: english/german | M44: no | N44: x
...
